[2025-04-01 07:25:23,275] INFO _log() L225   * Restarting with stat - call_trace=E:\Programacao\PUC\Pós-Graduação\MVPFullStack\todo-list-api\venv\Lib\site-packages\werkzeug\_internal.py L225 
[2025-04-01 07:25:42,504] WARNING post_usuario() L216  Error create user: Could not save this user :/, Exception: (sqlite3.OperationalError) no such column: usuarios.pk_usuario
[SQL: SELECT usuarios.pk_usuario AS usuarios_pk_usuario, usuarios.nome AS usuarios_nome, usuarios.email AS usuarios_email, usuarios.senha AS usuarios_senha, usuarios.tarefas AS usuarios_tarefas 
FROM usuarios 
WHERE usuarios.email = ?]
[parameters: ('rere',)]
(Background on this error at: https://sqlalche.me/e/14/e3q8) - call_trace=E:\Programacao\PUC\Pós-Graduação\MVPFullStack\todo-list-api\app.py L216 
[2025-04-01 07:32:07,876] INFO _log() L225   * Restarting with stat - call_trace=E:\Programacao\PUC\Pós-Graduação\MVPFullStack\todo-list-api\venv\Lib\site-packages\werkzeug\_internal.py L225 
[2025-04-01 07:33:21,875] WARNING add_tarefa() L103  Error adding task: Could not save new item :/, Exception: __init__() got an unexpected keyword argument 'data_criacao' - call_trace=E:\Programacao\PUC\Pós-Graduação\MVPFullStack\todo-list-api\app.py L103 
[2025-04-01 07:34:02,576] WARNING add_tarefa() L103  Error adding task: Could not save new item :/, Exception: __init__() got an unexpected keyword argument 'data_criacao' - call_trace=E:\Programacao\PUC\Pós-Graduação\MVPFullStack\todo-list-api\app.py L103 
[2025-04-01 07:35:27,373] INFO _log() L225   * Restarting with stat - call_trace=E:\Programacao\PUC\Pós-Graduação\MVPFullStack\todo-list-api\venv\Lib\site-packages\werkzeug\_internal.py L225 
[2025-04-01 07:36:03,689] INFO _log() L225   * Restarting with stat - call_trace=E:\Programacao\PUC\Pós-Graduação\MVPFullStack\todo-list-api\venv\Lib\site-packages\werkzeug\_internal.py L225 
[2025-04-01 07:36:07,989] INFO _log() L225   * Restarting with stat - call_trace=E:\Programacao\PUC\Pós-Graduação\MVPFullStack\todo-list-api\venv\Lib\site-packages\werkzeug\_internal.py L225 
[2025-04-01 07:36:18,318] WARNING add_tarefa() L103  Error adding task: Could not save new item :/, Exception: Incompatible collection type: None is not list-like - call_trace=E:\Programacao\PUC\Pós-Graduação\MVPFullStack\todo-list-api\app.py L103 
[2025-04-01 07:36:34,970] INFO _log() L225   * Restarting with stat - call_trace=E:\Programacao\PUC\Pós-Graduação\MVPFullStack\todo-list-api\venv\Lib\site-packages\werkzeug\_internal.py L225 
[2025-04-01 07:36:42,489] INFO _log() L225   * Restarting with stat - call_trace=E:\Programacao\PUC\Pós-Graduação\MVPFullStack\todo-list-api\venv\Lib\site-packages\werkzeug\_internal.py L225 
[2025-04-01 07:36:46,945] INFO _log() L225   * Restarting with stat - call_trace=E:\Programacao\PUC\Pós-Graduação\MVPFullStack\todo-list-api\venv\Lib\site-packages\werkzeug\_internal.py L225 
[2025-04-01 07:36:53,502] WARNING add_tarefa() L103  Error adding task: Could not save new item :/, Exception: Incompatible collection type: None is not list-like - call_trace=E:\Programacao\PUC\Pós-Graduação\MVPFullStack\todo-list-api\app.py L103 
[2025-04-01 07:37:06,816] INFO _log() L225   * Restarting with stat - call_trace=E:\Programacao\PUC\Pós-Graduação\MVPFullStack\todo-list-api\venv\Lib\site-packages\werkzeug\_internal.py L225 
[2025-04-01 07:37:08,176] INFO _log() L225   * Restarting with stat - call_trace=E:\Programacao\PUC\Pós-Graduação\MVPFullStack\todo-list-api\venv\Lib\site-packages\werkzeug\_internal.py L225 
[2025-04-01 07:37:14,337] WARNING add_tarefa() L90   User Not Found. - call_trace=E:\Programacao\PUC\Pós-Graduação\MVPFullStack\todo-list-api\app.py L90  
[2025-04-01 07:38:19,051] WARNING add_tarefa() L90   User Not Found. - call_trace=E:\Programacao\PUC\Pós-Graduação\MVPFullStack\todo-list-api\app.py L90  
[2025-04-01 07:38:46,139] WARNING add_tarefa() L90   User Not Found. - call_trace=E:\Programacao\PUC\Pós-Graduação\MVPFullStack\todo-list-api\app.py L90  
[2025-04-01 07:40:22,087] WARNING add_tarefa() L103  Error adding task: Could not save new item :/, Exception: Incompatible collection type: Usuario is not list-like - call_trace=E:\Programacao\PUC\Pós-Graduação\MVPFullStack\todo-list-api\app.py L103 
[2025-04-01 07:41:15,899] INFO _log() L225   * Restarting with stat - call_trace=E:\Programacao\PUC\Pós-Graduação\MVPFullStack\todo-list-api\venv\Lib\site-packages\werkzeug\_internal.py L225 
[2025-04-01 07:41:24,443] INFO _log() L225   * Restarting with stat - call_trace=E:\Programacao\PUC\Pós-Graduação\MVPFullStack\todo-list-api\venv\Lib\site-packages\werkzeug\_internal.py L225 
[2025-04-01 07:41:30,931] INFO _log() L225   * Restarting with stat - call_trace=E:\Programacao\PUC\Pós-Graduação\MVPFullStack\todo-list-api\venv\Lib\site-packages\werkzeug\_internal.py L225 
[2025-04-01 07:41:32,255] INFO _log() L225   * Restarting with stat - call_trace=E:\Programacao\PUC\Pós-Graduação\MVPFullStack\todo-list-api\venv\Lib\site-packages\werkzeug\_internal.py L225 
[2025-04-01 07:41:37,127] ERROR get_tarefas_por_status() L145  Error fetching tasks by status: (sqlite3.OperationalError) no such column: tarefa.usuario
[SQL: SELECT tarefa.pk_tarefa AS tarefa_pk_tarefa, tarefa.nome AS tarefa_nome, tarefa.descricao AS tarefa_descricao, tarefa.status AS tarefa_status, tarefa.data_criacao AS tarefa_data_criacao, tarefa.usuario AS tarefa_usuario 
FROM tarefa]
(Background on this error at: https://sqlalche.me/e/14/e3q8) - call_trace=E:\Programacao\PUC\Pós-Graduação\MVPFullStack\todo-list-api\app.py L145 
[2025-04-01 07:41:45,058] WARNING add_tarefa() L103  Error adding task: Could not save new item :/, Exception: (sqlite3.OperationalError) no such column: tarefa.usuario
[SQL: SELECT tarefa.pk_tarefa AS tarefa_pk_tarefa, tarefa.nome AS tarefa_nome, tarefa.descricao AS tarefa_descricao, tarefa.status AS tarefa_status, tarefa.data_criacao AS tarefa_data_criacao, tarefa.usuario AS tarefa_usuario 
FROM tarefa 
WHERE tarefa.nome = ?]
[parameters: ('rere',)]
(Background on this error at: https://sqlalche.me/e/14/e3q8) - call_trace=E:\Programacao\PUC\Pós-Graduação\MVPFullStack\todo-list-api\app.py L103 
[2025-04-01 07:43:41,984] INFO _log() L225   * Restarting with stat - call_trace=E:\Programacao\PUC\Pós-Graduação\MVPFullStack\todo-list-api\venv\Lib\site-packages\werkzeug\_internal.py L225 
[2025-04-01 07:43:54,138] WARNING add_tarefa() L90   User Not Found. - call_trace=E:\Programacao\PUC\Pós-Graduação\MVPFullStack\todo-list-api\app.py L90  
[2025-04-01 07:44:22,372] INFO _log() L225   * Restarting with stat - call_trace=E:\Programacao\PUC\Pós-Graduação\MVPFullStack\todo-list-api\venv\Lib\site-packages\werkzeug\_internal.py L225 
[2025-04-01 07:45:15,066] INFO _log() L225   * Restarting with stat - call_trace=E:\Programacao\PUC\Pós-Graduação\MVPFullStack\todo-list-api\venv\Lib\site-packages\werkzeug\_internal.py L225 
[2025-04-01 07:45:44,663] WARNING add_tarefa() L102  Error adding task: Could not save new item :/, Exception: (sqlite3.ProgrammingError) Error binding parameter 5: type 'Usuario' is not supported
[SQL: INSERT INTO tarefa (nome, descricao, status, data_criacao, usuario) VALUES (?, ?, ?, ?, ?)]
[parameters: ('rerre', 'rere', 'Ready', '2025-04-01 07:45:44.661822', <model.usuario.Usuario object at 0x00000171D0ECC090>)]
(Background on this error at: https://sqlalche.me/e/14/f405) - call_trace=E:\Programacao\PUC\Pós-Graduação\MVPFullStack\todo-list-api\app.py L102 
[2025-04-01 07:47:06,262] INFO _log() L225   * Restarting with stat - call_trace=E:\Programacao\PUC\Pós-Graduação\MVPFullStack\todo-list-api\venv\Lib\site-packages\werkzeug\_internal.py L225 
[2025-04-01 07:47:10,673] INFO _log() L225   * Restarting with stat - call_trace=E:\Programacao\PUC\Pós-Graduação\MVPFullStack\todo-list-api\venv\Lib\site-packages\werkzeug\_internal.py L225 
[2025-04-01 07:47:19,586] WARNING add_tarefa() L102  Error adding task: Could not save new item :/, Exception: (sqlite3.ProgrammingError) Error binding parameter 5: type 'Usuario' is not supported
[SQL: INSERT INTO tarefa (nome, descricao, status, data_criacao, usuario) VALUES (?, ?, ?, ?, ?)]
[parameters: ('rerer', 'rer', 'Ready', '2025-04-01 07:47:19.585249', <model.usuario.Usuario object at 0x000002759EE04910>)]
(Background on this error at: https://sqlalche.me/e/14/f405) - call_trace=E:\Programacao\PUC\Pós-Graduação\MVPFullStack\todo-list-api\app.py L102 
[2025-04-01 07:47:42,783] INFO _log() L225   * Restarting with stat - call_trace=E:\Programacao\PUC\Pós-Graduação\MVPFullStack\todo-list-api\venv\Lib\site-packages\werkzeug\_internal.py L225 
[2025-04-01 07:47:44,104] INFO _log() L225   * Restarting with stat - call_trace=E:\Programacao\PUC\Pós-Graduação\MVPFullStack\todo-list-api\venv\Lib\site-packages\werkzeug\_internal.py L225 
[2025-04-01 07:47:46,434] INFO _log() L225   * Restarting with stat - call_trace=E:\Programacao\PUC\Pós-Graduação\MVPFullStack\todo-list-api\venv\Lib\site-packages\werkzeug\_internal.py L225 
[2025-04-01 07:47:48,794] INFO _log() L225   * Restarting with stat - call_trace=E:\Programacao\PUC\Pós-Graduação\MVPFullStack\todo-list-api\venv\Lib\site-packages\werkzeug\_internal.py L225 
[2025-04-01 07:47:50,119] INFO _log() L225   * Restarting with stat - call_trace=E:\Programacao\PUC\Pós-Graduação\MVPFullStack\todo-list-api\venv\Lib\site-packages\werkzeug\_internal.py L225 
[2025-04-01 07:47:52,471] INFO _log() L225   * Restarting with stat - call_trace=E:\Programacao\PUC\Pós-Graduação\MVPFullStack\todo-list-api\venv\Lib\site-packages\werkzeug\_internal.py L225 
[2025-04-01 07:47:54,741] INFO _log() L225   * Restarting with stat - call_trace=E:\Programacao\PUC\Pós-Graduação\MVPFullStack\todo-list-api\venv\Lib\site-packages\werkzeug\_internal.py L225 
[2025-04-01 07:47:57,083] INFO _log() L225   * Restarting with stat - call_trace=E:\Programacao\PUC\Pós-Graduação\MVPFullStack\todo-list-api\venv\Lib\site-packages\werkzeug\_internal.py L225 
